Workbook

Sheet Petunjuk
A1: PETUNJUK PENGGUNAAN — ANALISIS AHP (SKALA 1-5) PEMBOBOTAN PSPI
A3: TUJUAN FILE INI
A4: Workbook ini menghitung bobot AHP (skala Saaty 1-5) untuk 4 dimensi Port Service Performance Index (PSPI):
A5: - CI = Compliance (Kepatuhan SLA)
A6: - EI = Efficiency (Efisiensi)
A7: - CsI = Consistency (Konsistensi)
A8: - RI = Robustness (Ketahanan)
A10: URUTAN PENGGUNAAN
A11: 1. Buka sheet 'Input Responden'. Salin jawaban dari Google Forms (setelah dikonversi ke angka bertanda -5..5
A12: sesuai tabel konversi pada dokumen kuesioner) ke sel BERWARNA KUNING pada sheet tersebut.
A13: 2. Buka sheet 'Perhitungan Detail' untuk melihat matriks perbandingan berpasangan, bobot, Lambda Max,
A14: Consistency Index (CI_AHP), dan Consistency Ratio (CR) per responden — semua terhitung otomatis.
... A52: responden lebih dari 10, namun perlu perluasan manual pada sheet 'Perhitungan Detail' dan 'Rekap Bobot Akhir'.

Sheet Input Responden
A1: INPUT DATA RESPONDEN — PERBANDINGAN BERPASANGAN (SKALA -5 s.d 5, TANPA 0)
D2: Setelah konversi | K2: Sebelum konversi
A3: No | B3: Nama Responden | C3: Institusi/Peran | D3: CI vs EI | E3: CI vs CsI | F3: CI vs RI | G3: EI vs CsI | H3: EI vs RI | I3: CsI vs RI | K3: CI vs EI | L3: CI vs CsI | M3: CI vs RI | N3: EI vs CsI | O3: EI vs RI | P3: CsI vs RI
A4: 1 | B4: Verina | C4: Operator/Petugas Otoritas Pelabuhan | D4: =IF(K4="","",IF(K4=5,1,IF(K4<5,6-K4,-(K4-4)))) -> 1 | E4: =IF(L4="","",IF(L4=5,1,IF(L4<5,6-L4,-(L4-4)))) -> 1 | F4: =IF(M4="","",IF(M4=5,1,IF(M4<5,6-M4,-(M4-4)))) -> 4 | G4: =IF(N4="","",IF(N4=5,1,IF(N4<5,6-N4,-(N4-4)))) -> 1 | H4: =IF(O4="","",IF(O4=5,1,IF(O4<5,6-O4,-(O4-4)))) -> 4 | I4: =IF(P4="","",IF(P4=5,1,IF(P4<5,6-P4,-(P4-4)))) -> 1 | K4: 5 | L4: 5 | M4: 2 | N4: 5 | O4: 2 | P4: 5
A5: 2 | B5: Agung Ginansah | C5: Pengguna jasa (perusahaan pelayaran/keagenan kapal) | D5: =IF(K5="","",IF(K5=5,1,IF(K5<5,6-K5,-(K5-4)))) -> -5 | E5: =IF(L5="","",IF(L5=5,1,IF(L5<5,6-L5,-(L5-4)))) -> -5 | F5: =IF(M5="","",IF(M5=5,1,IF(M5<5,6-M5,-(M5-4)))) -> 1 | G5: =IF(N5="","",IF(N5=5,1,IF(N5<5,6-N5,-(N5-4)))) -> -5 | H5: =IF(O5="","",IF(O5=5,1,IF(O5<5,6-O5,-(O5-4)))) -> 1 | I5: =IF(P5="","",IF(P5=5,1,IF(P5<5,6-P5,-(P5-4)))) -> 1 | K5: 9 | L5: 9 | M5: 5 | N5: 9 | O5: 5 | P5: 5
A6: 3 | B6: Andi | C6: Pengguna jasa (perusahaan pelayaran/keagenan kapal) | D6: =IF(K6="","",IF(K6=5,1,IF(K6<5,6-K6,-(K6-4)))) -> -4 | E6: =IF(L6="","",IF(L6=5,1,IF(L6<5,6-L6,-(L6-4)))) -> -4 | F6: =IF(M6="","",IF(M6=5,1,IF(M6<5,6-M6,-(M6-4)))) -> -4 | G6: =IF(N6="","",IF(N6=5,1,IF(N6<5,6-N6,-(N6-4)))) -> -4 | H6: =IF(O6="","",IF(O6=5,1,IF(O6<5,6-O6,-(O6-4)))) -> -4 | I6: =IF(P6="","",IF(P6=5,1,IF(P6<5,6-P6,-(P6-4)))) -> -4 | K6: 8 | L6: 8 | M6: 8 | N6: 8 | O6: 8 | P6: 8
A7: 4 | B7: Sarwo edi Wibowo | C7: Pengguna jasa (perusahaan pelayaran/keagenan kapal) | D7: =IF(K7="","",IF(K7=5,1,IF(K7<5,6-K7,-(K7-4)))) -> 1 | E7: =IF(L7="","",IF(L7=5,1,IF(L7<5,6-L7,-(L7-4)))) -> 1 | F7: =IF(M7="","",IF(M7=5,1,IF(M7<5,6-M7,-(M7-4)))) -> 5 | G7: =IF(N7="","",IF(N7=5,1,IF(N7<5,6-N7,-(N7-4)))) -> 1 | H7: =IF(O7="","",IF(O7=5,1,IF(O7<5,6-O7,-(O7-4)))) -> 5 | I7: =IF(P7="","",IF(P7=5,1,IF(P7<5,6-P7,-(P7-4)))) -> 5 | K7: 5 | L7: 5 | M7: 1 | N7: 5 | O7: 1 | P7: 1
A8: 5 | B8: Firman Ainur Rasyit | C8: Pengguna jasa (perusahaan pelayaran/keagenan kapal) | D8: =IF(K8="","",IF(K8=5,1,IF(K8<5,6-K8,-(K8-4)))) -> 5 | E8: =IF(L8="","",IF(L8=5,1,IF(L8<5,6-L8,-(L8-4)))) -> 5 | F8: =IF(M8="","",IF(M8=5,1,IF(M8<5,6-M8,-(M8-4)))) -> 5 | G8: =IF(N8="","",IF(N8=5,1,IF(N8<5,6-N8,-(N8-4)))) -> 5 | H8: =IF(O8="","",IF(O8=5,1,IF(O8<5,6-O8,-(O8-4)))) -> -5 | I8: =IF(P8="","",IF(P8=5,1,IF(P8<5,6-P8,-(P8-4)))) -> 1 | K8: 1 | L8: 1 | M8: 1 | N8: 1 | O8: 9 | P8: 5
A9: 6 | B9: Deny | C9: Pengguna jasa (perusahaan pelayaran/keagenan kapal) | D9: =IF(K9="","",IF(K9=5,1,IF(K9<5,6-K9,-(K9-4)))) -> 1 | E9: =IF(L9="","",IF(L9=5,1,IF(L9<5,6-L9,-(L9-4)))) -> -4 | F9: =IF(M9="","",IF(M9=5,1,IF(M9<5,6-M9,-(M9-4)))) -> 4 | G9: =IF(N9="","",IF(N9=5,1,IF(N9<5,6-N9,-(N9-4)))) -> 1 | H9: =IF(O9="","",IF(O9=5,1,IF(O9<5,6-O9,-(O9-4)))) -> 4 | I9: =IF(P9="","",IF(P9=5,1,IF(P9<5,6-P9,-(P9-4)))) -> 4 | K9: 5 | L9: 8 | M9: 2 | N9: 5 | O9: 2 | P9: 2
A10: 7 | B10: Eko Sukamto | C10: Operator/Petugas Otoritas Pelabuhan | D10: =IF(K10="","",IF(K10=5,1,IF(K10<5,6-K10,-(K10-4)))) -> 1 | E10: =IF(L10="","",IF(L10=5,1,IF(L10<5,6-L10,-(L10-4)))) -> 1 | F10: =IF(M10="","",IF(M10=5,1,IF(M10<5,6-M10,-(M10-4)))) -> 1 | G10: =IF(N10="","",IF(N10=5,1,IF(N10<5,6-N10,-(N10-4)))) -> 1 | H10: =IF(O10="","",IF(O10=5,1,IF(O10<5,6-O10,-(O10-4)))) -> 1 | I10: =IF(P10="","",IF(P10=5,1,IF(P10<5,6-P10,-(P10-4)))) -> 1 | K10: 5 | L10: 5 | M10: 5 | N10: 5 | O10: 5 | P10: 5
A11: 8 | B11: FERI HARIYANTO | C11: Pengguna jasa (perusahaan pelayaran/keagenan kapal) | D11: =IF(K11="","",IF(K11=5,1,IF(K11<5,6-K11,-(K11-4)))) -> 1 | E11: =IF(L11="","",IF(L11=5,1,IF(L11<5,6-L11,-(L11-4)))) -> 2 | F11: =IF(M11="","",IF(M11=5,1,IF(M11<5,6-M11,-(M11-4)))) -> 4 | G11: =IF(N11="","",IF(N11=5,1,IF(N11<5,6-N11,-(N11-4)))) -> -2 | H11: =IF(O11="","",IF(O11=5,1,IF(O11<5,6-O11,-(O11-4)))) -> 1 | I11: =IF(P11="","",IF(P11=5,1,IF(P11<5,6-P11,-(P11-4)))) -> 2 | K11: 5 | L11: 4 | M11: 2 | N11: 6 | O11: 5 | P11: 4
A12: 9 | B12: Glanny Sosbeldab Tatali | C12: Operator/Petugas Otoritas Pelabuhan | D12: =IF(K12="","",IF(K12=5,1,IF(K12<5,6-K12,-(K12-4)))) -> 1 | E12: =IF(L12="","",IF(L12=5,1,IF(L12<5,6-L12,-(L12-4)))) -> 1 | F12: =IF(M12="","",IF(M12=5,1,IF(M12<5,6-M12,-(M12-4)))) -> 1 | G12: =IF(N12="","",IF(N12=5,1,IF(N12<5,6-N12,-(N12-4)))) -> 1 | H12: =IF(O12="","",IF(O12=5,1,IF(O12<5,6-O12,-(O12-4)))) -> 5 | I12: =IF(P12="","",IF(P12=5,1,IF(P12<5,6-P12,-(P12-4)))) -> 5 | K12: 5 | L12: 5 | M12: 5 | N12: 5 | O12: 1 | P12: 1
A13: 10 | B13: Luthfi Setyawan | C13: Operator/Petugas Otoritas Pelabuhan | D13: =IF(K13="","",IF(K13=5,1,IF(K13<5,6-K13,-(K13-4)))) -> 5 | E13: =IF(L13="","",IF(L13=5,1,IF(L13<5,6-L13,-(L13-4)))) -> 4 | F13: =IF(M13="","",IF(M13=5,1,IF(M13<5,6-M13,-(M13-4)))) -> 5 | G13: =IF(N13="","",IF(N13=5,1,IF(N13<5,6-N13,-(N13-4)))) -> 4 | H13: =IF(O13="","",IF(O13=5,1,IF(O13<5,6-O13,-(O13-4)))) -> 5 | I13: =IF(P13="","",IF(P13=5,1,IF(P13<5,6-P13,-(P13-4)))) -> 5 | K13: 1 | L13: 2 | M13: 1 | N13: 2 | O13: 1 | P13: 1
A14: 11 | B14: Satrio Dwi Nugroho | C14: Pengguna jasa (perusahaan pelayaran/keagenan kapal) | D14: =IF(K14="","",IF(K14=5,1,IF(K14<5,6-K14,-(K14-4)))) -> 1 | E14: =IF(L14="","",IF(L14=5,1,IF(L14<5,6-L14,-(L14-4)))) -> 4 | F14: =IF(M14="","",IF(M14=5,1,IF(M14<5,6-M14,-(M14-4)))) -> 1 | G14: =IF(N14="","",IF(N14=5,1,IF(N14<5,6-N14,-(N14-4)))) -> 1 | H14: =IF(O14="","",IF(O14=5,1,IF(O14<5,6-O14,-(O14-4)))) -> 4 | I14: =IF(P14="","",IF(P14=5,1,IF(P14<5,6-P14,-(P14-4)))) -> 1 | K14: 5 | L14: 2 | M14: 5 | N14: 5 | O14: 2 | P14: 5
A15: 12 | B15: Alvaro Walewangko | C15: Pengguna jasa (perusahaan pelayaran/keagenan kapal) | D15: =IF(K15="","",IF(K15=5,1,IF(K15<5,6-K15,-(K15-4)))) -> -5 | E15: =IF(L15="","",IF(L15=5,1,IF(L15<5,6-L15,-(L15-4)))) -> -5 | F15: =IF(M15="","",IF(M15=5,1,IF(M15<5,6-M15,-(M15-4)))) -> -5 | G15: =IF(N15="","",IF(N15=5,1,IF(N15<5,6-N15,-(N15-4)))) -> -5 | H15: =IF(O15="","",IF(O15=5,1,IF(O15<5,6-O15,-(O15-4)))) -> -5 | I15: =IF(P15="","",IF(P15=5,1,IF(P15<5,6-P15,-(P15-4)))) -> -5 | K15: 9 | L15: 9 | M15: 9 | N15: 9 | O15: 9 | P15: 9
... A57: 54 | B57: Hendik mahmudi | C57: Pengguna jasa (perusahaan pelayaran/keagenan kapal) | D57: =IF(K57="","",IF(K57=5,1,IF(K57<5,6-K57,-(K57-4)))) -> 1 | E57: =IF(L57="","",IF(L57=5,1,IF(L57<5,6-L57,-(L57-4)))) -> 1 | F57: =IF(M57="","",IF(M57=5,1,IF(M57<5,6-M57,-(M57-4)))) -> 1 | G57: =IF(N57="","",IF(N57=5,1,IF(N57<5,6-N57,-(N57-4)))) -> 1 | H57: =IF(O57="","",IF(O57=5,1,IF(O57<5,6-O57,-(O57-4)))) -> 1 | I57: =IF(P57="","",IF(P57=5,1,IF(P57<5,6-P57,-(P57-4)))) -> 1 | K57: 5 | L57: 5 | M57: 5 | N57: 5 | O57: 5 | P57: 5
A58: 55
A59: 56
A60: 57
A61: 58
A62: 59
A63: 60
A65: Catatan: Baris 4 berisi CONTOH ilustratif — hapus/ganti dengan data responden sesungguhnya. Lihat sheet 'Petunjuk' untuk arti nilai -5 s.d 5.

Sheet Perhitungan Detail
A1: PERHITUNGAN DETAIL AHP PER RESPONDEN (Matriks, Bobot, Lambda Max, CI_AHP, CR)
A3: RESPONDEN 1: | B3: ='Input Responden'!B4 -> Verina
B4: CI | C4: EI | D4: CsI | E4: RI | G4: Bobot (w) | H4: A.w | I4: (A.w)/w
A5: CI | B5: 1 | C5: =IF('Input Responden'!D4>=0,IF('Input Responden'!D4=0,1,'Input Responden'!D4),1/ABS('Input Responden'!D4)) -> 1 | D5: =IF('Input Responden'!E4>=0,IF('Input Responden'!E4=0,1,'Input Responden'!E4),1/ABS('Input Responden'!E4)) -> 1 | E5: =IF('Input Responden'!F4>=0,IF('Input Responden'!F4=0,1,'Input Responden'!F4),1/ABS('Input Responden'!F4)) -> 4 | G5: =AVERAGE(B5/B$9,C5/C$9,D5/D$9,E5/E$9) -> 0.31634615 | H5: =B5*$G$5+C5*$G$6+D5*$G$7+E5*$G$8 -> 1.3778846 | I5: =H5/G5 -> 4.3556231
A6: EI | B6: =1/C5 -> 1 | C6: 1 | D6: =IF('Input Responden'!G4>=0,IF('Input Responden'!G4=0,1,'Input Responden'!G4),1/ABS('Input Responden'!G4)) -> 1 | E6: =IF('Input Responden'!H4>=0,IF('Input Responden'!H4=0,1,'Input Responden'!H4),1/ABS('Input Responden'!H4)) -> 4 | G6: =AVERAGE(B6/B$9,C6/C$9,D6/D$9,E6/E$9) -> 0.31634615 | H6: =B6*$G$5+C6*$G$6+D6*$G$7+E6*$G$8 -> 1.3778846 | I6: =H6/G6 -> 4.3556231
A7: CsI | B7: =1/D5 -> 1 | C7: =1/D6 -> 1 | D7: 1 | E7: =IF('Input Responden'!I4>=0,IF('Input Responden'!I4=0,1,'Input Responden'!I4),1/ABS('Input Responden'!I4)) -> 1 | G7: =AVERAGE(B7/B$9,C7/C$9,D7/D$9,E7/E$9) -> 0.24134615 | H7: =B7*$G$5+C7*$G$6+D7*$G$7+E7*$G$8 -> 1 | I7: =H7/G7 -> 4.1434263
A8: RI | B8: =1/E5 -> 0.25 | C8: =1/E6 -> 0.25 | D8: =1/E7 -> 1 | E8: 1 | G8: =AVERAGE(B8/B$9,C8/C$9,D8/D$9,E8/E$9) -> 0.12596154 | H8: =B8*$G$5+C8*$G$6+D8*$G$7+E8*$G$8 -> 0.52548077 | I8: =H8/G8 -> 4.1717557
A9: Jumlah Kolom | B9: =SUM(B5:B8) -> 3.25 | C9: =SUM(C5:C8) -> 3.25 | D9: =SUM(D5:D8) -> 4 | E9: =SUM(E5:E8) -> 10
A10: Lambda Max | G10: =AVERAGE(I5:I8) -> 4.2566071
A11: Consistency Index (CI_AHP) | G11: =(G10-4)/(4-1) -> 0.085535685
A12: Consistency Ratio (CR) [RI tabel n=4: 0.90] | G12: =G11/0.9 -> 0.09503965
A13: Keterangan | G13: =IF('Input Responden'!B4="","Belum diisi",IF(G12<=0.1,"Konsisten - dipakai","Tidak Konsisten - dikecualikan")) -> Konsisten - dipakai
A15: RESPONDEN 2: | B15: ='Input Responden'!B5 -> Agung Ginansah
B16: CI | C16: EI | D16: CsI | E16: RI | G16: Bobot (w) | H16: A.w | I16: (A.w)/w
A17: CI | B17: 1 | C17: =IF('Input Responden'!D5>=0,IF('Input Responden'!D5=0,1,'Input Responden'!D5),1/ABS('Input Responden'!D5)) -> 0.2 | D17: =IF('Input Responden'!E5>=0,IF('Input Responden'!E5=0,1,'Input Responden'!E5),1/ABS('Input Responden'!E5)) -> 0.2 | E17: =IF('Input Responden'!F5>=0,IF('Input Responden'!F5=0,1,'Input Responden'!F5),1/ABS('Input Responden'!F5)) -> 1 | G17: =AVERAGE(B17/B$21,C17/C$21,D17/D$21,E17/E$21) -> 0.11111111 | H17: =B17*$G$17+C17*$G$18+D17*$G$19+E17*$G$20 -> 0.46666667 | I17: =H17/G17 -> 4.2
A18: EI | B18: =1/C17 -> 5 | C18: 1 | D18: =IF('Input Responden'!G5>=0,IF('Input Responden'!G5=0,1,'Input Responden'!G5),1/ABS('Input Responden'!G5)) -> 0.2 | E18: =IF('Input Responden'!H5>=0,IF('Input Responden'!H5=0,1,'Input Responden'!H5),1/ABS('Input Responden'!H5)) -> 1 | G18: =AVERAGE(B18/B$21,C18/C$21,D18/D$21,E18/E$21) -> 0.22222222 | H18: =B18*$G$17+C18*$G$18+D18*$G$19+E18*$G$20 -> 1.0888889 | I18: =H18/G18 -> 4.9
A19: CsI | B19: =1/D17 -> 5 | C19: =1/D18 -> 5 | D19: 1 | E19: =IF('Input Responden'!I5>=0,IF('Input Responden'!I5=0,1,'Input Responden'!I5),1/ABS('Input Responden'!I5)) -> 1 | G19: =AVERAGE(B19/B$21,C19/C$21,D19/D$21,E19/E$21) -> 0.44444444 | H19: =B19*$G$17+C19*$G$18+D19*$G$19+E19*$G$20 -> 2.3333333 | I19: =H19/G19 -> 5.25
A20: RI | B20: =1/E17 -> 1 | C20: =1/E18 -> 1 | D20: =1/E19 -> 1 | E20: 1 | G20: =AVERAGE(B20/B$21,C20/C$21,D20/D$21,E20/E$21) -> 0.22222222 | H20: =B20*$G$17+C20*$G$18+D20*$G$19+E20*$G$20 -> 1 | I20: =H20/G20 -> 4.5
A21: Jumlah Kolom | B21: =SUM(B17:B20) -> 12 | C21: =SUM(C17:C20) -> 7.2 | D21: =SUM(D17:D20) -> 2.4 | E21: =SUM(E17:E20) -> 4
A22: Lambda Max | G22: =AVERAGE(I17:I20) -> 4.7125
A23: Consistency Index (CI_AHP) | G23: =(G22-4)/(4-1) -> 0.2375
A24: Consistency Ratio (CR) [RI tabel n=4: 0.90] | G24: =G23/0.9 -> 0.26388889
A25: Keterangan | G25: =IF('Input Responden'!B5="","Belum diisi",IF(G24<=0.1,"Konsisten - dipakai","Tidak Konsisten - dikecualikan")) -> Tidak Konsisten - dikecualikan
A27: RESPONDEN 3: | B27: ='Input Responden'!B6 -> Andi
B28: CI | C28: EI | D28: CsI | E28: RI | G28: Bobot (w) | H28: A.w | I28: (A.w)/w
A29: CI | B29: 1 | C29: =IF('Input Responden'!D6>=0,IF('Input Responden'!D6=0,1,'Input Responden'!D6),1/ABS('Input Responden'!D6)) -> 0.25 | D29: =IF('Input Responden'!E6>=0,IF('Input Responden'!E6=0,1,'Input Responden'!E6),1/ABS('Input Responden'!E6)) -> 0.25 | E29: =IF('Input Responden'!F6>=0,IF('Input Responden'!F6=0,1,'Input Responden'!F6),1/ABS('Input Responden'!F6)) -> 0.25 | G29: =AVERAGE(B29/B$33,C29/C$33,D29/D$33,E29/E$33) -> 0.073065448 | H29: =B29*$G$29+C29*$G$30+D29*$G$31+E29*$G$32 -> 0.30479909 | I29: =H29/G29 -> 4.1715899
A30: EI | B30: =1/C29 -> 4 | C30: 1 | D30: =IF('Input Responden'!G6>=0,IF('Input Responden'!G6=0,1,'Input Responden'!G6),1/ABS('Input Responden'!G6)) -> 0.25 | E30: =IF('Input Responden'!H6>=0,IF('Input Responden'!H6=0,1,'Input Responden'!H6),1/ABS('Input Responden'!H6)) -> 0.25 | G30: =AVERAGE(B30/B$33,C30/C$33,D30/D$33,E30/E$33) -> 0.15102803 | H30: =B30*$G$29+C30*$G$30+D30*$G$31+E30*$G$32 -> 0.63726645 | I30: =H30/G30 -> 4.2195245
A31: CsI | B31: =1/D29 -> 4 | C31: =1/D30 -> 4 | D31: 1 | E31: =IF('Input Responden'!I6>=0,IF('Input Responden'!I6=0,1,'Input Responden'!I6),1/ABS('Input Responden'!I6)) -> 0.25 | G31: =AVERAGE(B31/B$33,C31/C$33,D31/D$33,E31/E$33) -> 0.26620002 | H31: =B31*$G$29+C31*$G$30+D31*$G$31+E31*$G$32 -> 1.2900005 | I31: =H31/G31 -> 4.8459822
A32: RI | B32: =1/E29 -> 4 | C32: =1/E30 -> 4 | D32: =1/E31 -> 4 | E32: 1 | G32: =AVERAGE(B32/B$33,C32/C$33,D32/D$33,E32/E$33) -> 0.50970651 | H32: =B32*$G$29+C32*$G$30+D32*$G$31+E32*$G$32 -> 2.4708805 | I32: =H32/G32 -> 4.8476534
A33: Jumlah Kolom | B33: =SUM(B29:B32) -> 13 | C33: =SUM(C29:C32) -> 9.25 | D33: =SUM(D29:D32) -> 5.5 | E33: =SUM(E29:E32) -> 1.75
A34: Lambda Max | G34: =AVERAGE(I29:I32) -> 4.5211875
A35: Consistency Index (CI_AHP) | G35: =(G34-4)/(4-1) -> 0.17372916
A36: Consistency Ratio (CR) [RI tabel n=4: 0.90] | G36: =G35/0.9 -> 0.1930324
A37: Keterangan | G37: =IF('Input Responden'!B6="","Belum diisi",IF(G36<=0.1,"Konsisten - dipakai","Tidak Konsisten - dikecualikan")) -> Tidak Konsisten - dikecualikan
A39: RESPONDEN 4: | B39: ='Input Responden'!B7 -> Sarwo edi Wibowo
B40: CI | C40: EI | D40: CsI | E40: RI | G40: Bobot (w) | H40: A.w | I40: (A.w)/w
A41: CI | B41: 1 | C41: =IF('Input Responden'!D7>=0,IF('Input Responden'!D7=0,1,'Input Responden'!D7),1/ABS('Input Responden'!D7)) -> 1 | D41: =IF('Input Responden'!E7>=0,IF('Input Responden'!E7=0,1,'Input Responden'!E7),1/ABS('Input Responden'!E7)) -> 1 | E41: =IF('Input Responden'!F7>=0,IF('Input Responden'!F7=0,1,'Input Responden'!F7),1/ABS('Input Responden'!F7)) -> 5 | G41: =AVERAGE(B41/B$45,C41/C$45,D41/D$45,E41/E$45) -> 0.3125 | H41: =B41*$G$41+C41*$G$42+D41*$G$43+E41*$G$44 -> 1.25 | I41: =H41/G41 -> 4
A42: EI | B42: =1/C41 -> 1 | C42: 1 | D42: =IF('Input Responden'!G7>=0,IF('Input Responden'!G7=0,1,'Input Responden'!G7),1/ABS('Input Responden'!G7)) -> 1 | E42: =IF('Input Responden'!H7>=0,IF('Input Responden'!H7=0,1,'Input Responden'!H7),1/ABS('Input Responden'!H7)) -> 5 | G42: =AVERAGE(B42/B$45,C42/C$45,D42/D$45,E42/E$45) -> 0.3125 | H42: =B42*$G$41+C42*$G$42+D42*$G$43+E42*$G$44 -> 1.25 | I42: =H42/G42 -> 4
A43: CsI | B43: =1/D41 -> 1 | C43: =1/D42 -> 1 | D43: 1 | E43: =IF('Input Responden'!I7>=0,IF('Input Responden'!I7=0,1,'Input Responden'!I7),1/ABS('Input Responden'!I7)) -> 5 | G43: =AVERAGE(B43/B$45,C43/C$45,D43/D$45,E43/E$45) -> 0.3125 | H43: =B43*$G$41+C43*$G$42+D43*$G$43+E43*$G$44 -> 1.25 | I43: =H43/G43 -> 4
A44: RI | B44: =1/E41 -> 0.2 | C44: =1/E42 -> 0.2 | D44: =1/E43 -> 0.2 | E44: 1 | G44: =AVERAGE(B44/B$45,C44/C$45,D44/D$45,E44/E$45) -> 0.0625 | H44: =B44*$G$41+C44*$G$42+D44*$G$43+E44*$G$44 -> 0.25 | I44: =H44/G44 -> 4
...

Sheet Rekap Bobot Akhir
A1: REKAP BOBOT SELURUH RESPONDEN DAN BOBOT AKHIR (AGREGASI)
A3: No | B3: Nama Responden | C3: w_CI | D3: w_EI | E3: w_CsI | F3: w_RI | G3: CR | H3: Keterangan
A4: 1 | B4: ='Perhitungan Detail'!B3 -> Verina | C4: ='Perhitungan Detail'!G5 -> 0.31634615 | D4: ='Perhitungan Detail'!G6 -> 0.31634615 | E4: ='Perhitungan Detail'!G7 -> 0.24134615 | F4: ='Perhitungan Detail'!G8 -> 0.12596154 | G4: ='Perhitungan Detail'!G12 -> 0.09503965 | H4: ='Perhitungan Detail'!G13 -> Konsisten - dipakai
A5: 2 | B5: ='Perhitungan Detail'!B15 -> Agung Ginansah | C5: ='Perhitungan Detail'!G17 -> 0.11111111 | D5: ='Perhitungan Detail'!G18 -> 0.22222222 | E5: ='Perhitungan Detail'!G19 -> 0.44444444 | F5: ='Perhitungan Detail'!G20 -> 0.22222222 | G5: ='Perhitungan Detail'!G24 -> 0.26388889 | H5: ='Perhitungan Detail'!G25 -> Tidak Konsisten - dikecualikan
A6: 3 | B6: ='Perhitungan Detail'!B27 -> Andi | C6: ='Perhitungan Detail'!G29 -> 0.073065448 | D6: ='Perhitungan Detail'!G30 -> 0.15102803 | E6: ='Perhitungan Detail'!G31 -> 0.26620002 | F6: ='Perhitungan Detail'!G32 -> 0.50970651 | G6: ='Perhitungan Detail'!G36 -> 0.1930324 | H6: ='Perhitungan Detail'!G37 -> Tidak Konsisten - dikecualikan
A7: 4 | B7: ='Perhitungan Detail'!B39 -> Sarwo edi Wibowo | C7: ='Perhitungan Detail'!G41 -> 0.3125 | D7: ='Perhitungan Detail'!G42 -> 0.3125 | E7: ='Perhitungan Detail'!G43 -> 0.3125 | F7: ='Perhitungan Detail'!G44 -> 0.0625 | G7: ='Perhitungan Detail'!G48 -> 0 | H7: ='Perhitungan Detail'!G49 -> Konsisten - dipakai
A8: 5 | B8: ='Perhitungan Detail'!B51 -> Firman Ainur Rasyit | C8: ='Perhitungan Detail'!G53 -> 0.54563492 | D8: ='Perhitungan Detail'!G54 -> 0.16468254 | E8: ='Perhitungan Detail'!G55 -> 0.091269841 | F8: ='Perhitungan Detail'!G56 -> 0.1984127 | G8: ='Perhitungan Detail'!G60 -> 0.43784907 | H8: ='Perhitungan Detail'!G61 -> Tidak Konsisten - dikecualikan
A9: 6 | B9: ='Perhitungan Detail'!B63 -> Deny | C9: ='Perhitungan Detail'!G65 -> 0.21884615 | D9: ='Perhitungan Detail'!G66 -> 0.29384615 | E9: ='Perhitungan Detail'!G67 -> 0.41384615 | F9: ='Perhitungan Detail'!G68 -> 0.073461538 | G9: ='Perhitungan Detail'!G72 -> 0.092571383 | H9: ='Perhitungan Detail'!G73 -> Konsisten - dipakai
A10: 7 | B10: ='Perhitungan Detail'!B75 -> Eko Sukamto | C10: ='Perhitungan Detail'!G77 -> 0.25 | D10: ='Perhitungan Detail'!G78 -> 0.25 | E10: ='Perhitungan Detail'!G79 -> 0.25 | F10: ='Perhitungan Detail'!G80 -> 0.25 | G10: ='Perhitungan Detail'!G84 -> 0 | H10: ='Perhitungan Detail'!G85 -> Konsisten - dipakai
A11: 8 | B11: ='Perhitungan Detail'!B87 -> FERI HARIYANTO | C11: ='Perhitungan Detail'!G89 -> 0.39090909 | D11: ='Perhitungan Detail'!G90 -> 0.20340909 | E11: ='Perhitungan Detail'!G91 -> 0.27045455 | F11: ='Perhitungan Detail'!G92 -> 0.13522727 | G11: ='Perhitungan Detail'!G96 -> 0.091941561 | H11: ='Perhitungan Detail'!G97 -> Konsisten - dipakai
A12: 9 | B12: ='Perhitungan Detail'!B99 -> Glanny Sosbeldab Tatali | C12: ='Perhitungan Detail'!G101 -> 0.23958333 | D12: ='Perhitungan Detail'!G102 -> 0.32291667 | E12: ='Perhitungan Detail'!G103 -> 0.32291667 | F12: ='Perhitungan Detail'!G104 -> 0.11458333 | G12: ='Perhitungan Detail'!G108 -> 0.13188453 | H12: ='Perhitungan Detail'!G109 -> Tidak Konsisten - dikecualikan
A13: 10 | B13: ='Perhitungan Detail'!B111 -> Luthfi Setyawan | C13: ='Perhitungan Detail'!G113 -> 0.53213425 | D13: ='Perhitungan Detail'!G114 -> 0.25588337 | E13: ='Perhitungan Detail'!G115 -> 0.15286762 | F13: ='Perhitungan Detail'!G116 -> 0.059114751 | G13: ='Perhitungan Detail'!G120 -> 0.22916959 | H13: ='Perhitungan Detail'!G121 -> Tidak Konsisten - dikecualikan
A14: 11 | B14: ='Perhitungan Detail'!B123 -> Satrio Dwi Nugroho | C14: ='Perhitungan Detail'!G125 -> 0.33241758 | D14: ='Perhitungan Detail'!G126 -> 0.33241758 | E14: ='Perhitungan Detail'!G127 -> 0.16758242 | F14: ='Perhitungan Detail'!G128 -> 0.16758242 | G14: ='Perhitungan Detail'!G132 -> 0.18521655 | H14: ='Perhitungan Detail'!G133 -> Tidak Konsisten - dikecualikan
A15: 12 | B15: ='Perhitungan Detail'!B135 -> Alvaro Walewangko | C15: ='Perhitungan Detail'!G137 -> 0.059151786 | D15: ='Perhitungan Detail'!G138 -> 0.13950893 | E15: ='Perhitungan Detail'!G139 -> 0.26004464 | F15: ='Perhitungan Detail'!G140 -> 0.54129464 | G15: ='Perhitungan Detail'!G144 -> 0.27065713 | H15: ='Perhitungan Detail'!G145 -> Tidak Konsisten - dikecualikan
A16: 13 | B16: ='Perhitungan Detail'!B147 -> Aditya mulyanto | C16: ='Perhitungan Detail'!G149 -> 0.54129464 | D16: ='Perhitungan Detail'!G150 -> 0.26004464 | E16: ='Perhitungan Detail'!G151 -> 0.13950893 | F16: ='Perhitungan Detail'!G152 -> 0.059151786 | G16: ='Perhitungan Detail'!G156 -> 0.27065713 | H16: ='Perhitungan Detail'!G157 -> Tidak Konsisten - dikecualikan
A17: 14 | B17: ='Perhitungan Detail'!B159 -> RIKKI APRIANTO SADIA | C17: ='Perhitungan Detail'!G161 -> 0.54129464 | D17: ='Perhitungan Detail'!G162 -> 0.26004464 | E17: ='Perhitungan Detail'!G163 -> 0.13950893 | F17: ='Perhitungan Detail'!G164 -> 0.059151786 | G17: ='Perhitungan Detail'!G168 -> 0.27065713 | H17: ='Perhitungan Detail'!G169 -> Tidak Konsisten - dikecualikan
A18: 15 | B18: ='Perhitungan Detail'!B171 -> MUH.YUSUF KALLA | C18: ='Perhitungan Detail'!G173 -> 0.54129464 | D18: ='Perhitungan Detail'!G174 -> 0.26004464 | E18: ='Perhitungan Detail'!G175 -> 0.13950893 | F18: ='Perhitungan Detail'!G176 -> 0.059151786 | G18: ='Perhitungan Detail'!G180 -> 0.27065713 | H18: ='Perhitungan Detail'!G181 -> Tidak Konsisten - dikecualikan
A19: 16 | B19: ='Perhitungan Detail'!B183 -> MUH HUSAIN FAUZAN | C19: ='Perhitungan Detail'!G185 -> 0.25 | D19: ='Perhitungan Detail'!G186 -> 0.25 | E19: ='Perhitungan Detail'!G187 -> 0.25 | F19: ='Perhitungan Detail'!G188 -> 0.25 | G19: ='Perhitungan Detail'!G192 -> 0 | H19: ='Perhitungan Detail'!G193 -> Konsisten - dipakai
A20: 17 | B20: ='Perhitungan Detail'!B195 -> ROKI SAPUTRA | C20: ='Perhitungan Detail'!G197 -> 0.54129464 | D20: ='Perhitungan Detail'!G198 -> 0.26004464 | E20: ='Perhitungan Detail'!G199 -> 0.13950893 | F20: ='Perhitungan Detail'!G200 -> 0.059151786 | G20: ='Perhitungan Detail'!G204 -> 0.27065713 | H20: ='Perhitungan Detail'!G205 -> Tidak Konsisten - dikecualikan
A21: 18 | B21: ='Perhitungan Detail'!B207 -> Dimas | C21: ='Perhitungan Detail'!G209 -> 0.25 | D21: ='Perhitungan Detail'!G210 -> 0.25 | E21: ='Perhitungan Detail'!G211 -> 0.25 | F21: ='Perhitungan Detail'!G212 -> 0.25 | G21: ='Perhitungan Detail'!G216 -> 0 | H21: ='Perhitungan Detail'!G217 -> Konsisten - dipakai
A22: 19 | B22: ='Perhitungan Detail'!B219 -> Fandi | C22: ='Perhitungan Detail'!G221 -> 0.46298701 | D22: ='Perhitungan Detail'!G222 -> 0.27251082 | E22: ='Perhitungan Detail'!G223 -> 0.16861472 | F22: ='Perhitungan Detail'!G224 -> 0.095887446 | G22: ='Perhitungan Detail'!G228 -> 0.11674255 | H22: ='Perhitungan Detail'!G229 -> Tidak Konsisten - dikecualikan
A23: 20 | B23: ='Perhitungan Detail'!B231 -> ACHMAD SHOLEH | C23: ='Perhitungan Detail'!G233 -> 0.54129464 | D23: ='Perhitungan Detail'!G234 -> 0.13950893 | E23: ='Perhitungan Detail'!G235 -> 0.26004464 | F23: ='Perhitungan Detail'!G236 -> 0.059151786 | G23: ='Perhitungan Detail'!G240 -> 0.27065713 | H23: ='Perhitungan Detail'!G241 -> Tidak Konsisten - dikecualikan
A24: 21 | B24: ='Perhitungan Detail'!B243 -> Sulaeman | C24: ='Perhitungan Detail'!G245 -> 0.073065448 | D24: ='Perhitungan Detail'!G246 -> 0.15102803 | E24: ='Perhitungan Detail'!G247 -> 0.26620002 | F24: ='Perhitungan Detail'!G248 -> 0.50970651 | G24: ='Perhitungan Detail'!G252 -> 0.1930324 | H24: ='Perhitungan Detail'!G253 -> Tidak Konsisten - dikecualikan
A25: 22 | B25: ='Perhitungan Detail'!B255 -> Suharyadih | C25: ='Perhitungan Detail'!G257 -> 0.54129464 | D25: ='Perhitungan Detail'!G258 -> 0.26004464 | E25: ='Perhitungan Detail'!G259 -> 0.13950893 | F25: ='Perhitungan Detail'!G260 -> 0.059151786 | G25: ='Perhitungan Detail'!G264 -> 0.27065713 | H25: ='Perhitungan Detail'!G265 -> Tidak Konsisten - dikecualikan
A26: 23 | B26: ='Perhitungan Detail'!B267 -> Iksan sanjaya | C26: ='Perhitungan Detail'!G269 -> 0.54129464 | D26: ='Perhitungan Detail'!G270 -> 0.26004464 | E26: ='Perhitungan Detail'!G271 -> 0.13950893 | F26: ='Perhitungan Detail'!G272 -> 0.059151786 | G26: ='Perhitungan Detail'!G276 -> 0.27065713 | H26: ='Perhitungan Detail'!G277 -> Tidak Konsisten - dikecualikan
A27: 24 | B27: ='Perhitungan Detail'!B279 -> Tri Candra | C27: ='Perhitungan Detail'!G281 -> 0.46298701 | D27: ='Perhitungan Detail'!G282 -> 0.27251082 | E27: ='Perhitungan Detail'!G283 -> 0.16861472 | F27: ='Perhitungan Detail'!G284 -> 0.095887446 | G27: ='Perhitungan Detail'!G288 -> 0.11674255 | H27: ='Perhitungan Detail'!G289 -> Tidak Konsisten - dikecualikan
A28: 25 | B28: ='Perhitungan Detail'!B291 -> Taufan IM | C28: ='Perhitungan Detail'!G293 -> 0.25 | D28: ='Perhitungan Detail'!G294 -> 0.25 | E28: ='Perhitungan Detail'!G295 -> 0.25 | F28: ='Perhitungan Detail'!G296 -> 0.25 | G28: ='Perhitungan Detail'!G300 -> 0 | H28: ='Perhitungan Detail'!G301 -> Konsisten - dipakai
A29: 26 | B29: ='Perhitungan Detail'!B303 -> Nurdin | C29: ='Perhitungan Detail'!G305 -> 0.17760618 | D29: ='Perhitungan Detail'!G306 -> 0.17760618 | E29: ='Perhitungan Detail'!G307 -> 0.46718147 | F29: ='Perhitungan Detail'!G308 -> 0.17760618 | G29: ='Perhitungan Detail'!G312 -> 0.6745194 | H29: ='Perhitungan Detail'!G313 -> Tidak Konsisten - dikecualikan
A30: 27 | B30: ='Perhitungan Detail'!B315 -> Agus Setia | C30: ='Perhitungan Detail'!G317 -> 0.31914736 | D30: ='Perhitungan Detail'!G318 -> 0.28464795 | E30: ='Perhitungan Detail'!G319 -> 0.060791741 | F30: ='Perhitungan Detail'!G320 -> 0.33541295 | G30: ='Perhitungan Detail'!G324 -> 0.56618405 | H30: ='Perhitungan Detail'!G325 -> Tidak Konsisten - dikecualikan
A31: 28 | B31: ='Perhitungan Detail'!B327 -> Iskandar Y Taroka | C31: ='Perhitungan Detail'!G329 -> 0.25 | D31: ='Perhitungan Detail'!G330 -> 0.25 | E31: ='Perhitungan Detail'!G331 -> 0.25 | F31: ='Perhitungan Detail'!G332 -> 0.25 | G31: ='Perhitungan Detail'!G336 -> 0 | H31: ='Perhitungan Detail'!G337 -> Konsisten - dipakai
A32: 29 | B32: ='Perhitungan Detail'!B339 -> Firdaus Dwi Marta Al Mansur | C32: ='Perhitungan Detail'!G341 -> 0.26620002 | D32: ='Perhitungan Detail'!G342 -> 0.50970651 | E32: ='Perhitungan Detail'!G343 -> 0.15102803 | F32: ='Perhitungan Detail'!G344 -> 0.073065448 | G32: ='Perhitungan Detail'!G348 -> 0.1930324 | H32: ='Perhitungan Detail'!G349 -> Tidak Konsisten - dikecualikan
A33: 30 | B33: ='Perhitungan Detail'!B351 -> KADEK GHUSTY RAMAYANA, A.Md.Tra | C33: ='Perhitungan Detail'!G353 -> 0.25 | D33: ='Perhitungan Detail'!G354 -> 0.25 | E33: ='Perhitungan Detail'!G355 -> 0.25 | F33: ='Perhitungan Detail'!G356 -> 0.25 | G33: ='Perhitungan Detail'!G360 -> 0 | H33: ='Perhitungan Detail'!G361 -> Konsisten - dipakai
A34: 31 | B34: ='Perhitungan Detail'!B363 -> Faisal Fadhiil | C34: ='Perhitungan Detail'!G365 -> 0.31160714 | D34: ='Perhitungan Detail'!G366 -> 0.28035714 | E34: ='Perhitungan Detail'!G367 -> 0.28035714 | F34: ='Perhitungan Detail'!G368 -> 0.12767857 | G34: ='Perhitungan Detail'!G372 -> 0.0076447492 | H34: ='Perhitungan Detail'!G373 -> Konsisten - dipakai
A35: 32 | B35: ='Perhitungan Detail'!B375 -> Akbar | C35: ='Perhitungan Detail'!G377 -> 0.31634615 | D35: ='Perhitungan Detail'!G378 -> 0.31634615 | E35: ='Perhitungan Detail'!G379 -> 0.24134615 | F35: ='Perhitungan Detail'!G380 -> 0.12596154 | G35: ='Perhitungan Detail'!G384 -> 0.09503965 | H35: ='Perhitungan Detail'!G385 -> Konsisten - dipakai
A36: 33 | B36: ='Perhitungan Detail'!B387 -> BAGUS MAULANA | C36: ='Perhitungan Detail'!G389 -> 0.10243132 | D36: ='Perhitungan Detail'!G390 -> 0.15112291 | E36: ='Perhitungan Detail'!G391 -> 0.53882328 | F36: ='Perhitungan Detail'!G392 -> 0.20762249 | G36: ='Perhitungan Detail'!G396 -> 0.088668868 | H36: ='Perhitungan Detail'!G397 -> Konsisten - dipakai
A37: 34 | B37: ='Perhitungan Detail'!B399 -> Sulaksono prasetyo | C37: ='Perhitungan Detail'!G401 -> 0.54129464 | D37: ='Perhitungan Detail'!G402 -> 0.13950893 | E37: ='Perhitungan Detail'!G403 -> 0.26004464 | F37: ='Perhitungan Detail'!G404 -> 0.059151786 | G37: ='Perhitungan Detail'!G408 -> 0.27065713 | H37: ='Perhitungan Detail'!G409 -> Tidak Konsisten - dikecualikan
A38: 35 | B38: ='Perhitungan Detail'!B411 -> Eko | C38: ='Perhitungan Detail'!G413 -> 0.50970651 | D38: ='Perhitungan Detail'!G414 -> 0.26620002 | E38: ='Perhitungan Detail'!G415 -> 0.15102803 | F38: ='Perhitungan Detail'!G416 -> 0.073065448 | G38: ='Perhitungan Detail'!G420 -> 0.1930324 | H38: ='Perhitungan Detail'!G421 -> Tidak Konsisten - dikecualikan
A39: 36 | B39: ='Perhitungan Detail'!B423 -> TRENDI NUGROHO | C39: ='Perhitungan Detail'!G425 -> 0.51534133 | D39: ='Perhitungan Detail'!G426 -> 0.26704575 | E39: ='Perhitungan Detail'!G427 -> 0.14582996 | F39: ='Perhitungan Detail'!G428 -> 0.071782959 | G39: ='Perhitungan Detail'!G432 -> 0.27064973 | H39: ='Perhitungan Detail'!G433 -> Tidak Konsisten - dikecualikan
A40: 37 | B40: ='Perhitungan Detail'!B435 -> YOVIKA FIRMANSYAH | C40: ='Perhitungan Detail'!G437 -> 0.059151786 | D40: ='Perhitungan Detail'!G438 -> 0.13950893 | E40: ='Perhitungan Detail'!G439 -> 0.26004464 | F40: ='Perhitungan Detail'!G440 -> 0.54129464 | G40: ='Perhitungan Detail'!G444 -> 0.27065713 | H40: ='Perhitungan Detail'!G445 -> Tidak Konsisten - dikecualikan
A41: 38 | B41: ='Perhitungan Detail'!B447 -> irwan budi | C41: ='Perhitungan Detail'!G449 -> 0.234375 | D41: ='Perhitungan Detail'!G450 -> 0.359375 | E41: ='Perhitungan Detail'!G451 -> 0.234375 | F41: ='Perhitungan Detail'!G452 -> 0.171875 | G41: ='Perhitungan Detail'!G456 -> 0.12726297 | H41: ='Perhitungan Detail'!G457 -> Tidak Konsisten - dikecualikan
...

Sheet Simulasi PI
A1: SIMULASI PENERAPAN BOBOT AKHIR TERHADAP DATA KINERJA PELABUHAN (CONTOH)
A2: Data contoh di bawah diambil dari Tabel 6 & 7 draf paper (skor sudah ternormalisasi 0-1 per dimensi). Ganti/tambahkan baris sesuai data 259 pelabuhan yang sesungguhnya untuk analisis penuh.
A4: Pelabuhan | B4: Volume | C4: CI | D4: EI | E4: CsI | F4: RI | G4: PI Equal (0.25 tiap dimensi) | H4: PI Bobot AHP | I4: Selisih (AHP - Equal) | J4: Kategori (Equal) | K4: Kategori (AHP, ilustratif)
A5: NABIRE | B5: 703 | C5: 1 | D5: 1 | E5: 1 | F5: 1 | G5: =0.25*C5+0.25*D5+0.25*E5+0.25*F5 -> 1 | H5: ='Rekap Bobot Akhir'!$B$70*C5+'Rekap Bobot Akhir'!$C$70*D5+'Rekap Bobot Akhir'!$D$70*E5+'Rekap Bobot Akhir'!$E$70*F5 -> 1 | I5: =H5-G5 -> 0 | J5: =IF(G5>=0.5,"Performa Tinggi","Performa Rendah") -> Performa Tinggi | K5: =IF(H5>=0.5,"Performa Tinggi","Performa Rendah") -> Performa Tinggi
A6: TG. SARANG ELANG | B6: 28 | C6: 1 | D6: 1 | E6: 1 | F6: 1 | G6: =0.25*C6+0.25*D6+0.25*E6+0.25*F6 -> 1 | H6: ='Rekap Bobot Akhir'!$B$70*C6+'Rekap Bobot Akhir'!$C$70*D6+'Rekap Bobot Akhir'!$D$70*E6+'Rekap Bobot Akhir'!$E$70*F6 -> 1 | I6: =H6-G6 -> 0 | J6: =IF(G6>=0.5,"Performa Tinggi","Performa Rendah") -> Performa Tinggi | K6: =IF(H6>=0.5,"Performa Tinggi","Performa Rendah") -> Performa Tinggi
A7: BAWEAN | B7: 922 | C7: 1 | D7: 1 | E7: 1 | F7: 1 | G7: =0.25*C7+0.25*D7+0.25*E7+0.25*F7 -> 1 | H7: ='Rekap Bobot Akhir'!$B$70*C7+'Rekap Bobot Akhir'!$C$70*D7+'Rekap Bobot Akhir'!$D$70*E7+'Rekap Bobot Akhir'!$E$70*F7 -> 1 | I7: =H7-G7 -> 0 | J7: =IF(G7>=0.5,"Performa Tinggi","Performa Rendah") -> Performa Tinggi | K7: =IF(H7>=0.5,"Performa Tinggi","Performa Rendah") -> Performa Tinggi
A8: INDRAMAYU | B8: 1877 | C8: 1 | D8: 1 | E8: 1 | F8: 1 | G8: =0.25*C8+0.25*D8+0.25*E8+0.25*F8 -> 1 | H8: ='Rekap Bobot Akhir'!$B$70*C8+'Rekap Bobot Akhir'!$C$70*D8+'Rekap Bobot Akhir'!$D$70*E8+'Rekap Bobot Akhir'!$E$70*F8 -> 1 | I8: =H8-G8 -> 0 | J8: =IF(G8>=0.5,"Performa Tinggi","Performa Rendah") -> Performa Tinggi | K8: =IF(H8>=0.5,"Performa Tinggi","Performa Rendah") -> Performa Tinggi
A9: MANGGAR | B9: 1201 | C9: 1 | D9: 0.9995 | E9: 1 | F9: 1 | G9: =0.25*C9+0.25*D9+0.25*E9+0.25*F9 -> 0.999875 | H9: ='Rekap Bobot Akhir'!$B$70*C9+'Rekap Bobot Akhir'!$C$70*D9+'Rekap Bobot Akhir'!$D$70*E9+'Rekap Bobot Akhir'!$E$70*F9 -> 0.99986505 | I9: =H9-G9 -> -9.94747e-06 | J9: =IF(G9>=0.5,"Performa Tinggi","Performa Rendah") -> Performa Tinggi | K9: =IF(H9>=0.5,"Performa Tinggi","Performa Rendah") -> Performa Tinggi
A10: SATUI | B10: 8085 | C10: 0 | D10: 0.0465 | E10: 0.9813 | F10: 0 | G10: =0.25*C10+0.25*D10+0.25*E10+0.25*F10 -> 0.25695 | H10: ='Rekap Bobot Akhir'!$B$70*C10+'Rekap Bobot Akhir'!$C$70*D10+'Rekap Bobot Akhir'!$D$70*E10+'Rekap Bobot Akhir'!$E$70*F10 -> 0.29791157 | I10: =H10-G10 -> 0.040961568 | J10: =IF(G10>=0.5,"Performa Tinggi","Performa Rendah") -> Performa Rendah | K10: =IF(H10>=0.5,"Performa Tinggi","Performa Rendah") -> Performa Rendah
A11: PANGKAL BALAM, BANGKA | B11: 5323 | C11: 0.0161 | D11: 0 | E11: 0.8601 | F11: 0 | G11: =0.25*C11+0.25*D11+0.25*E11+0.25*F11 -> 0.21905 | H11: ='Rekap Bobot Akhir'!$B$70*C11+'Rekap Bobot Akhir'!$C$70*D11+'Rekap Bobot Akhir'!$D$70*E11+'Rekap Bobot Akhir'!$E$70*F11 -> 0.25426006 | I11: =H11-G11 -> 0.035210055 | J11: =IF(G11>=0.5,"Performa Tinggi","Performa Rendah") -> Performa Rendah | K11: =IF(H11>=0.5,"Performa Tinggi","Performa Rendah") -> Performa Rendah
A12: PADANG BAI | B12: 10960 | C12: 0 | D12: 0.2879 | E12: 0 | F12: 0.3329 | G12: =0.25*C12+0.25*D12+0.25*E12+0.25*F12 -> 0.1552 | H12: ='Rekap Bobot Akhir'!$B$70*C12+'Rekap Bobot Akhir'!$C$70*D12+'Rekap Bobot Akhir'!$D$70*E12+'Rekap Bobot Akhir'!$E$70*F12 -> 0.13827259 | I12: =H12-G12 -> -0.016927406 | J12: =IF(G12>=0.5,"Performa Tinggi","Performa Rendah") -> Performa Rendah | K12: =IF(H12>=0.5,"Performa Tinggi","Performa Rendah") -> Performa Rendah
A13: MOLAWE | B13: 17487 | C13: 0 | D13: 0.2568 | E13: 0.0115 | F13: 0 | G13: =0.25*C13+0.25*D13+0.25*E13+0.25*F13 -> 0.067075 | H13: ='Rekap Bobot Akhir'!$B$70*C13+'Rekap Bobot Akhir'!$C$70*D13+'Rekap Bobot Akhir'!$D$70*E13+'Rekap Bobot Akhir'!$E$70*F13 -> 0.072653214 | I13: =H13-G13 -> 0.0055782137 | J13: =IF(G13>=0.5,"Performa Tinggi","Performa Rendah") -> Performa Rendah | K13: =IF(H13>=0.5,"Performa Tinggi","Performa Rendah") -> Performa Rendah
A14: KUALA SEMBOJA | B14: 10577 | C14: 0.039 | D14: 0 | E14: 0.1671 | F14: 0 | G14: =0.25*C14+0.25*D14+0.25*E14+0.25*F14 -> 0.051525 | H14: ='Rekap Bobot Akhir'!$B$70*C14+'Rekap Bobot Akhir'!$C$70*D14+'Rekap Bobot Akhir'!$D$70*E14+'Rekap Bobot Akhir'!$E$70*F14 -> 0.058629605 | I14: =H14-G14 -> 0.0071046047 | J14: =IF(G14>=0.5,"Performa Tinggi","Performa Rendah") -> Performa Rendah | K14: =IF(H14>=0.5,"Performa Tinggi","Performa Rendah") -> Performa Rendah
A16: Catatan: Kolom Kategori di atas HANYA ilustrasi biner (tinggi/rendah terhadap ambang 0.5), bukan klasifikasi kuadran penuh (yang memerlukan median Volume & PI dari seluruh 259 pelabuhan). Untuk analisis kuadran lengkap, terapkan bobot akhir dari sheet 'Rekap Bobot Akhir' ke seluruh dataset asli lalu ulangi prosedur median-threshold seperti pada paper (Bagian 2c).
